Workbook

Sheet Raw Data
A1: Employee ID | B1: Full Name | C1: Department | D1: Email | E1: Salary | F1: Joining Date | G1: Bonus | H1: Manager
A2: 101 | B2: Ram Kumar | C2: HR | D2: ram@gmail.com | E2: 25000 | F2: 44938 | G2: 2000 | H2: Suresh
A3: 102 | B3: sita devi | C3: IT | D3: sita@gmail.com | E3: 30000 | F3: 44972 | H3: Mahesh
A4: 103 | B4: Ravi Kumar | C4: Sales | D4: ravi@gmail.com | E4: 28000 | F4: 45003 | G4: 2500 | H4: Suresh
A5: 104 | B5: Meena Sharma | C5: IT | D5: meena@gmail.com | E5: 35000 | F5: 45037 | G5: 3000
A6: 105 | B6: JOHN RAO | C6: Finance | D6: john@gmail.com | E6: 40000 | F6: 45071 | G6: 4000 | H6: Kavitha
A7: 106 | B7: Kavya Reddy | C7: IT | D7: kavya@gmail.com | F7: 45078 | G7: 1500 | H7: Mahesh
A8: 107 | B8: Arjun Naik | C8: Sales | D8: arjun@gmail.com | E8: 27000 | F8: 45088 | H8: Suresh
A9: 108 | B9: priya sharma | C9: HR | D9: priya@gmail.com | E9: 26000 | F9: 45126 | G9: 1800 | H9: Kavitha
A10: 109 | B10: Rohit Verma | C10: Finance | D10: rohit@gmail.com | E10: 38000 | F10: 45160 | G10: 3500 | H10: Kavitha
A11: 110 | B11: Sneha Iyer | C11: IT | D11: sneha@gmail.com | E11: 32000 | F11: 45174 | H11: Mahesh
A12: 111 | B12: Vikram Singh | C12: Sales | D12: vikram@gmail.com | E12: 29000 | F12: 45179 | G12: 2100
A13: 112 | B13: Anjali Mehta | C13: HR | D13: anjali@gmail.com | E13: 27000 | F13: 45217 | G13: 2000 | H13: Suresh
A14: 113 | B14: Raj Patel | C14: Finance | D14: raj@gmail.com | E14: 42000 | F14: 45221 | G14: 4500 | H14: Kavitha
A15: 114 | B15: Neha Joshi | C15: IT | D15: neha@gmail.com | F15: 45260 | G15: 1700 | H15: Mahesh
A16: 115 | B16: Kiran Das | C16: Sales | D16: kiran@gmail.com | E16: 26000 | F16: 45275 | H16: Suresh
A17: 116 | B17: Pooja Nair | C17: HR | D17: pooja@gmail.com | E17: 28000 | F17: 45296 | G17: 1900 | H17: Kavitha
A18: 117 | B18: Aman Gupta | C18: Finance | D18: aman@gmail.com | E18: 39000 | F18: 45303 | G18: 3600 | H18: Kavitha
A19: 118 | B19: Ritu Jain | C19: IT | D19: ritu@gmail.com | E19: 31000 | F19: 45316 | H19: Mahesh
A20: 119 | B20: Mohan Rao | C20: Sales | D20: mohan@gmail.com | E20: 27500 | F20: 45323 | G20: 2000 | H20: Suresh
A21: 120 | B21: Sunita Devi | C21: HR | D21: sunita@gmail.com | E21: 26500 | F21: 45332 | G21: 1800 | H21: Kavitha
A22: 121 | B22: Deepak Kumar | C22: IT | D22: deepak@gmail.com | E22: 33000 | F22: 45337 | G22: 2200 | H22: Mahesh
A23: 122 | B23: Varun Kapoor | C23: Finance | D23: varun@gmail.com | F23: 45342 | G23: 3000 | H23: Kavitha
A24: 123 | B24: Nisha Verma | C24: Sales | D24: nisha@gmail.com | E24: 29500 | F24: 45352 | H24: Suresh
A25: 124 | B25: Rahul Singh | C25: HR | D25: rahul@gmail.com | E25: 28500 | F25: 45356 | G25: 2100 | H25: Kavitha
A26: 125 | B26: Kavita Sharma | C26: IT | D26: kavita@gmail.com | E26: 34000 | F26: 45361 | H26: Mahesh
A27: 126 | B27: Tarun Mehta | C27: Finance | D27: tarun@gmail.com | E27: 41000 | F27: 45366 | G27: 3800 | H27: Kavitha
A28: 127 | B28: Pawan Kumar | C28: Sales | D28: pawan@gmail.com | E28: 26500 | F28: 45371 | H28: Suresh
A29: 128 | B29: Divya Nair | C29: HR | D29: divya@gmail.com | F29: 45376 | G29: 1900 | H29: Kavitha
A30: 129 | B30: Karthik Rao | C30: IT | D30: karthik@gmail.com | E30: 36000 | F30: 45383 | H30: Mahesh
A31: 130 | B31: Rekha Das | C31: Finance | D31: rekha@gmail.com | E31: 43000 | F31: 45387 | G31: 4000 | H31: Kavitha
A32: 131 | B32: Ram kumar | C32: HR | D32: ram@gmail.com | E32: 25000 | F32: 44938 | G32: 2000 | H32: Suresh
A33: 132 | B33: SITA DEVI | C33: IT | D33: sita@gmail.com | E33: 30000 | F33: 44972 | H33: Mahesh
A34: 133 | B34: Ravi Kumar | C34: Sales | D34: ravi@gmail.com | E34: 28000 | F34: 45003 | G34: 2500 | H34: Suresh
A35: 134 | B35: Meena sharma | C35: IT | D35: meena@gmail.com | E35: 35000 | F35: 45037 | G35: 3000
A36: 135 | B36: John Rao | C36: Finance | D36: john@gmail.com | E36: 40000 | F36: 45071 | G36: 4000 | H36: Kavitha
A37: 136 | B37: Kavya reddy | C37: IT | D37: kavya@gmail.com | F37: 45078 | G37: 1500 | H37: Mahesh
A38: 137 | B38: Arjun naik | C38: Sales | D38: arjun@gmail.com | E38: 27000 | F38: 45088 | H38: Suresh
A39: 138 | B39: Priya Sharma | C39: HR | D39: priya@gmail.com | E39: 26000 | F39: 45126 | G39: 1800 | H39: Kavitha
A40: 139 | B40: Rohit verma | C40: Finance | D40: rohit@gmail.com | E40: 38000 | F40: 45160 | G40: 3500 | H40: Kavitha
...

Sheet Cleaned data
A1: Employee ID | B1: Full Name | C1: Clean Name | D1: Department | E1: Clean dept | F1: Email | G1: Clean Email | H1: Salary | I1: Clean Salary | J1: Joining Date | K1: Bonus | L1: Clean Bonus | M1: Manager | N1: Clean manager | O1: Total Pay
A2: 101 | B2: Ram Kumar | C2: =PROPER(TRIM(B2)) -> Ram Kumar | D2: HR | E2: =PROPER(TRIM(D2)) -> Hr | F2: ram@gmail.com | G2: =IF(F2="","Not Available",F2) -> ram@gmail.com | H2: 25000 | I2: =IF(H2="",$H$93,H2) -> 25000 | J2: 44938 | K2: 2000 | L2: =IF(K2="",0,K2) -> 2000 | M2: Suresh | N2: =IF(M2="","Not Assigned",M2) -> Suresh | O2: =IFERROR(I2+L2,0) -> 27000
A3: 102 | B3: sita devi | C3: =PROPER(TRIM(B3)) -> Sita Devi | D3: IT | E3: =PROPER(TRIM(D3)) -> It | F3: sita@gmail.com | G3: =IF(F3="","Not Available",F3) -> sita@gmail.com | H3: 30000 | I3: =IF(H3="",$H$93,H3) -> 30000 | J3: 44972 | L3: =IF(K3="",0,K3) -> 0 | M3: Mahesh | N3: =IF(M3="","Not Assigned",M3) -> Mahesh | O3: =IFERROR(I3+L3,0) -> 30000
A4: 103 | B4: Ravi Kumar | C4: =PROPER(TRIM(B4)) -> Ravi Kumar | D4: Sales | E4: =PROPER(TRIM(D4)) -> Sales | F4: ravi@gmail.com | G4: =IF(F4="","Not Available",F4) -> ravi@gmail.com | H4: 28000 | I4: =IF(H4="",$H$93,H4) -> 28000 | J4: 45003 | K4: 2500 | L4: =IF(K4="",0,K4) -> 2500 | M4: Suresh | N4: =IF(M4="","Not Assigned",M4) -> Suresh | O4: =IFERROR(I4+L4,0) -> 30500
A5: 104 | B5: Meena Sharma | C5: =PROPER(TRIM(B5)) -> Meena Sharma | D5: IT | E5: =PROPER(TRIM(D5)) -> It | F5: meena@gmail.com | G5: =IF(F5="","Not Available",F5) -> meena@gmail.com | H5: 35000 | I5: =IF(H5="",$H$93,H5) -> 35000 | J5: 45037 | K5: 3000 | L5: =IF(K5="",0,K5) -> 3000 | N5: =IF(M5="","Not Assigned",M5) -> Not Assigned | O5: =IFERROR(I5+L5,0) -> 38000
A6: 105 | B6: JOHN RAO | C6: =PROPER(TRIM(B6)) -> John Rao | D6: Finance | E6: =PROPER(TRIM(D6)) -> Finance | F6: john@gmail.com | G6: =IF(F6="","Not Available",F6) -> john@gmail.com | H6: 40000 | I6: =IF(H6="",$H$93,H6) -> 40000 | J6: 45071 | K6: 4000 | L6: =IF(K6="",0,K6) -> 4000 | M6: Kavitha | N6: =IF(M6="","Not Assigned",M6) -> Kavitha | O6: =IFERROR(I6+L6,0) -> 44000 | Q6: What i have done: Remove Duplicates Fix Text Formatting Handle Missing Salary Handle Missing Bonus Handle Missing Email Handle Missing Manager Create Total Pay column
A7: 106 | B7: Kavya Reddy | C7: =PROPER(TRIM(B7)) -> Kavya Reddy | D7: IT | E7: =PROPER(TRIM(D7)) -> It | F7: kavya@gmail.com | G7: =IF(F7="","Not Available",F7) -> kavya@gmail.com | I7: =IF(H7="",$H$93,H7) -> 32091 | J7: 45078 | K7: 1500 | L7: =IF(K7="",0,K7) -> 1500 | M7: Mahesh | N7: =IF(M7="","Not Assigned",M7) -> Mahesh | O7: =IFERROR(I7+L7,0) -> 33591
A8: 107 | B8: Arjun Naik | C8: =PROPER(TRIM(B8)) -> Arjun Naik | D8: Sales | E8: =PROPER(TRIM(D8)) -> Sales | F8: arjun@gmail.com | G8: =IF(F8="","Not Available",F8) -> arjun@gmail.com | H8: 27000 | I8: =IF(H8="",$H$93,H8) -> 27000 | J8: 45088 | L8: =IF(K8="",0,K8) -> 0 | M8: Suresh | N8: =IF(M8="","Not Assigned",M8) -> Suresh | O8: =IFERROR(I8+L8,0) -> 27000
A9: 108 | B9: priya sharma | C9: =PROPER(TRIM(B9)) -> Priya Sharma | D9: HR | E9: =PROPER(TRIM(D9)) -> Hr | F9: priya@gmail.com | G9: =IF(F9="","Not Available",F9) -> priya@gmail.com | H9: 26000 | I9: =IF(H9="",$H$93,H9) -> 26000 | J9: 45126 | K9: 1800 | L9: =IF(K9="",0,K9) -> 1800 | M9: Kavitha | N9: =IF(M9="","Not Assigned",M9) -> Kavitha | O9: =IFERROR(I9+L9,0) -> 27800
A10: 109 | B10: Rohit Verma | C10: =PROPER(TRIM(B10)) -> Rohit Verma | D10: Finance | E10: =PROPER(TRIM(D10)) -> Finance | F10: rohit@gmail.com | G10: =IF(F10="","Not Available",F10) -> rohit@gmail.com | H10: 38000 | I10: =IF(H10="",$H$93,H10) -> 38000 | J10: 45160 | K10: 3500 | L10: =IF(K10="",0,K10) -> 3500 | M10: Kavitha | N10: =IF(M10="","Not Assigned",M10) -> Kavitha | O10: =IFERROR(I10+L10,0) -> 41500
A11: 110 | B11: Sneha Iyer | C11: =PROPER(TRIM(B11)) -> Sneha Iyer | D11: IT | E11: =PROPER(TRIM(D11)) -> It | F11: sneha@gmail.com | G11: =IF(F11="","Not Available",F11) -> sneha@gmail.com | H11: 32000 | I11: =IF(H11="",$H$93,H11) -> 32000 | J11: 45174 | L11: =IF(K11="",0,K11) -> 0 | M11: Mahesh | N11: =IF(M11="","Not Assigned",M11) -> Mahesh | O11: =IFERROR(I11+L11,0) -> 32000
A12: 111 | B12: Vikram Singh | C12: =PROPER(TRIM(B12)) -> Vikram Singh | D12: Sales | E12: =PROPER(TRIM(D12)) -> Sales | F12: vikram@gmail.com | G12: =IF(F12="","Not Available",F12) -> vikram@gmail.com | H12: 29000 | I12: =IF(H12="",$H$93,H12) -> 29000 | J12: 45179 | K12: 2100 | L12: =IF(K12="",0,K12) -> 2100 | N12: =IF(M12="","Not Assigned",M12) -> Not Assigned | O12: =IFERROR(I12+L12,0) -> 31100
A13: 112 | B13: Anjali Mehta | C13: =PROPER(TRIM(B13)) -> Anjali Mehta | D13: HR | E13: =PROPER(TRIM(D13)) -> Hr | F13: anjali@gmail.com | G13: =IF(F13="","Not Available",F13) -> anjali@gmail.com | H13: 27000 | I13: =IF(H13="",$H$93,H13) -> 27000 | J13: 45217 | K13: 2000 | L13: =IF(K13="",0,K13) -> 2000 | M13: Suresh | N13: =IF(M13="","Not Assigned",M13) -> Suresh | O13: =IFERROR(I13+L13,0) -> 29000
A14: 113 | B14: Raj Patel | C14: =PROPER(TRIM(B14)) -> Raj Patel | D14: Finance | E14: =PROPER(TRIM(D14)) -> Finance | F14: raj@gmail.com | G14: =IF(F14="","Not Available",F14) -> raj@gmail.com | H14: 42000 | I14: =IF(H14="",$H$93,H14) -> 42000 | J14: 45221 | K14: 4500 | L14: =IF(K14="",0,K14) -> 4500 | M14: Kavitha | N14: =IF(M14="","Not Assigned",M14) -> Kavitha | O14: =IFERROR(I14+L14,0) -> 46500
A15: 114 | B15: Neha Joshi | C15: =PROPER(TRIM(B15)) -> Neha Joshi | D15: IT | E15: =PROPER(TRIM(D15)) -> It | F15: neha@gmail.com | G15: =IF(F15="","Not Available",F15) -> neha@gmail.com | I15: =IF(H15="",$H$93,H15) -> 32091 | J15: 45260 | K15: 1700 | L15: =IF(K15="",0,K15) -> 1700 | M15: Mahesh | N15: =IF(M15="","Not Assigned",M15) -> Mahesh | O15: =IFERROR(I15+L15,0) -> 33791
A16: 115 | B16: Kiran Das | C16: =PROPER(TRIM(B16)) -> Kiran Das | D16: Sales | E16: =PROPER(TRIM(D16)) -> Sales | F16: kiran@gmail.com | G16: =IF(F16="","Not Available",F16) -> kiran@gmail.com | H16: 26000 | I16: =IF(H16="",$H$93,H16) -> 26000 | J16: 45275 | L16: =IF(K16="",0,K16) -> 0 | M16: Suresh | N16: =IF(M16="","Not Assigned",M16) -> Suresh | O16: =IFERROR(I16+L16,0) -> 26000
A17: 116 | B17: Pooja Nair | C17: =PROPER(TRIM(B17)) -> Pooja Nair | D17: HR | E17: =PROPER(TRIM(D17)) -> Hr | F17: pooja@gmail.com | G17: =IF(F17="","Not Available",F17) -> pooja@gmail.com | H17: 28000 | I17: =IF(H17="",$H$93,H17) -> 28000 | J17: 45296 | K17: 1900 | L17: =IF(K17="",0,K17) -> 1900 | M17: Kavitha | N17: =IF(M17="","Not Assigned",M17) -> Kavitha | O17: =IFERROR(I17+L17,0) -> 29900
A18: 117 | B18: Aman Gupta | C18: =PROPER(TRIM(B18)) -> Aman Gupta | D18: Finance | E18: =PROPER(TRIM(D18)) -> Finance | F18: aman@gmail.com | G18: =IF(F18="","Not Available",F18) -> aman@gmail.com | H18: 39000 | I18: =IF(H18="",$H$93,H18) -> 39000 | J18: 45303 | K18: 3600 | L18: =IF(K18="",0,K18) -> 3600 | M18: Kavitha | N18: =IF(M18="","Not Assigned",M18) -> Kavitha | O18: =IFERROR(I18+L18,0) -> 42600
A19: 118 | B19: Ritu Jain | C19: =PROPER(TRIM(B19)) -> Ritu Jain | D19: IT | E19: =PROPER(TRIM(D19)) -> It | F19: ritu@gmail.com | G19: =IF(F19="","Not Available",F19) -> ritu@gmail.com | H19: 31000 | I19: =IF(H19="",$H$93,H19) -> 31000 | J19: 45316 | L19: =IF(K19="",0,K19) -> 0 | M19: Mahesh | N19: =IF(M19="","Not Assigned",M19) -> Mahesh | O19: =IFERROR(I19+L19,0) -> 31000
A20: 119 | B20: Mohan Rao | C20: =PROPER(TRIM(B20)) -> Mohan Rao | D20: Sales | E20: =PROPER(TRIM(D20)) -> Sales | F20: mohan@gmail.com | G20: =IF(F20="","Not Available",F20) -> mohan@gmail.com | H20: 27500 | I20: =IF(H20="",$H$93,H20) -> 27500 | J20: 45323 | K20: 2000 | L20: =IF(K20="",0,K20) -> 2000 | M20: Suresh | N20: =IF(M20="","Not Assigned",M20) -> Suresh | O20: =IFERROR(I20+L20,0) -> 29500
A21: 120 | B21: Sunita Devi | C21: =PROPER(TRIM(B21)) -> Sunita Devi | D21: HR | E21: =PROPER(TRIM(D21)) -> Hr | F21: sunita@gmail.com | G21: =IF(F21="","Not Available",F21) -> sunita@gmail.com | H21: 26500 | I21: =IF(H21="",$H$93,H21) -> 26500 | J21: 45332 | K21: 1800 | L21: =IF(K21="",0,K21) -> 1800 | M21: Kavitha | N21: =IF(M21="","Not Assigned",M21) -> Kavitha | O21: =IFERROR(I21+L21,0) -> 28300
A22: 121 | B22: Deepak Kumar | C22: =PROPER(TRIM(B22)) -> Deepak Kumar | D22: IT | E22: =PROPER(TRIM(D22)) -> It | F22: deepak@gmail.com | G22: =IF(F22="","Not Available",F22) -> deepak@gmail.com | H22: 33000 | I22: =IF(H22="",$H$93,H22) -> 33000 | J22: 45337 | K22: 2200 | L22: =IF(K22="",0,K22) -> 2200 | M22: Mahesh | N22: =IF(M22="","Not Assigned",M22) -> Mahesh | O22: =IFERROR(I22+L22,0) -> 35200
A23: 122 | B23: Varun Kapoor | C23: =PROPER(TRIM(B23)) -> Varun Kapoor | D23: Finance | E23: =PROPER(TRIM(D23)) -> Finance | F23: varun@gmail.com | G23: =IF(F23="","Not Available",F23) -> varun@gmail.com | I23: =IF(H23="",$H$93,H23) -> 32091 | J23: 45342 | K23: 3000 | L23: =IF(K23="",0,K23) -> 3000 | M23: Kavitha | N23: =IF(M23="","Not Assigned",M23) -> Kavitha | O23: =IFERROR(I23+L23,0) -> 35091
A24: 123 | B24: Nisha Verma | C24: =PROPER(TRIM(B24)) -> Nisha Verma | D24: Sales | E24: =PROPER(TRIM(D24)) -> Sales | F24: nisha@gmail.com | G24: =IF(F24="","Not Available",F24) -> nisha@gmail.com | H24: 29500 | I24: =IF(H24="",$H$93,H24) -> 29500 | J24: 45352 | L24: =IF(K24="",0,K24) -> 0 | M24: Suresh | N24: =IF(M24="","Not Assigned",M24) -> Suresh | O24: =IFERROR(I24+L24,0) -> 29500
A25: 124 | B25: Rahul Singh | C25: =PROPER(TRIM(B25)) -> Rahul Singh | D25: HR | E25: =PROPER(TRIM(D25)) -> Hr | F25: rahul@gmail.com | G25: =IF(F25="","Not Available",F25) -> rahul@gmail.com | H25: 28500 | I25: =IF(H25="",$H$93,H25) -> 28500 | J25: 45356 | K25: 2100 | L25: =IF(K25="",0,K25) -> 2100 | M25: Kavitha | N25: =IF(M25="","Not Assigned",M25) -> Kavitha | O25: =IFERROR(I25+L25,0) -> 30600
A26: 125 | B26: Kavita Sharma | C26: =PROPER(TRIM(B26)) -> Kavita Sharma | D26: IT | E26: =PROPER(TRIM(D26)) -> It | F26: kavita@gmail.com | G26: =IF(F26="","Not Available",F26) -> kavita@gmail.com | H26: 34000 | I26: =IF(H26="",$H$93,H26) -> 34000 | J26: 45361 | L26: =IF(K26="",0,K26) -> 0 | M26: Mahesh | N26: =IF(M26="","Not Assigned",M26) -> Mahesh | O26: =IFERROR(I26+L26,0) -> 34000
A27: 126 | B27: Tarun Mehta | C27: =PROPER(TRIM(B27)) -> Tarun Mehta | D27: Finance | E27: =PROPER(TRIM(D27)) -> Finance | F27: tarun@gmail.com | G27: =IF(F27="","Not Available",F27) -> tarun@gmail.com | H27: 41000 | I27: =IF(H27="",$H$93,H27) -> 41000 | J27: 45366 | K27: 3800 | L27: =IF(K27="",0,K27) -> 3800 | M27: Kavitha | N27: =IF(M27="","Not Assigned",M27) -> Kavitha | O27: =IFERROR(I27+L27,0) -> 44800
A28: 127 | B28: Pawan Kumar | C28: =PROPER(TRIM(B28)) -> Pawan Kumar | D28: Sales | E28: =PROPER(TRIM(D28)) -> Sales | F28: pawan@gmail.com | G28: =IF(F28="","Not Available",F28) -> pawan@gmail.com | H28: 26500 | I28: =IF(H28="",$H$93,H28) -> 26500 | J28: 45371 | L28: =IF(K28="",0,K28) -> 0 | M28: Suresh | N28: =IF(M28="","Not Assigned",M28) -> Suresh | O28: =IFERROR(I28+L28,0) -> 26500
A29: 128 | B29: Divya Nair | C29: =PROPER(TRIM(B29)) -> Divya Nair | D29: HR | E29: =PROPER(TRIM(D29)) -> Hr | F29: divya@gmail.com | G29: =IF(F29="","Not Available",F29) -> divya@gmail.com | I29: =IF(H29="",$H$93,H29) -> 32091 | J29: 45376 | K29: 1900 | L29: =IF(K29="",0,K29) -> 1900 | M29: Kavitha | N29: =IF(M29="","Not Assigned",M29) -> Kavitha | O29: =IFERROR(I29+L29,0) -> 33991
A30: 129 | B30: Karthik Rao | C30: =PROPER(TRIM(B30)) -> Karthik Rao | D30: IT | E30: =PROPER(TRIM(D30)) -> It | F30: karthik@gmail.com | G30: =IF(F30="","Not Available",F30) -> karthik@gmail.com | H30: 36000 | I30: =IF(H30="",$H$93,H30) -> 36000 | J30: 45383 | L30: =IF(K30="",0,K30) -> 0 | M30: Mahesh | N30: =IF(M30="","Not Assigned",M30) -> Mahesh | O30: =IFERROR(I30+L30,0) -> 36000
A31: 130 | B31: Rekha Das | C31: =PROPER(TRIM(B31)) -> Rekha Das | D31: Finance | E31: =PROPER(TRIM(D31)) -> Finance | F31: rekha@gmail.com | G31: =IF(F31="","Not Available",F31) -> rekha@gmail.com | H31: 43000 | I31: =IF(H31="",$H$93,H31) -> 43000 | J31: 45387 | K31: 4000 | L31: =IF(K31="",0,K31) -> 4000 | M31: Kavitha | N31: =IF(M31="","Not Assigned",M31) -> Kavitha | O31: =IFERROR(I31+L31,0) -> 47000
A32: 131 | B32: Ram kumar | C32: =PROPER(TRIM(B32)) -> Ram Kumar | D32: HR | E32: =PROPER(TRIM(D32)) -> Hr | F32: ram@gmail.com | G32: =IF(F32="","Not Available",F32) -> ram@gmail.com | H32: 25000 | I32: =IF(H32="",$H$93,H32) -> 25000 | J32: 44938 | K32: 2000 | L32: =IF(K32="",0,K32) -> 2000 | M32: Suresh | N32: =IF(M32="","Not Assigned",M32) -> Suresh | O32: =IFERROR(I32+L32,0) -> 27000
A33: 132 | B33: SITA DEVI | C33: =PROPER(TRIM(B33)) -> Sita Devi | D33: IT | E33: =PROPER(TRIM(D33)) -> It | F33: sita@gmail.com | G33: =IF(F33="","Not Available",F33) -> sita@gmail.com | H33: 30000 | I33: =IF(H33="",$H$93,H33) -> 30000 | J33: 44972 | L33: =IF(K33="",0,K33) -> 0 | M33: Mahesh | N33: =IF(M33="","Not Assigned",M33) -> Mahesh | O33: =IFERROR(I33+L33,0) -> 30000
A34: 133 | B34: Ravi Kumar | C34: =PROPER(TRIM(B34)) -> Ravi Kumar | D34: Sales | E34: =PROPER(TRIM(D34)) -> Sales | F34: ravi@gmail.com | G34: =IF(F34="","Not Available",F34) -> ravi@gmail.com | H34: 28000 | I34: =IF(H34="",$H$93,H34) -> 28000 | J34: 45003 | K34: 2500 | L34: =IF(K34="",0,K34) -> 2500 | M34: Suresh | N34: =IF(M34="","Not Assigned",M34) -> Suresh | O34: =IFERROR(I34+L34,0) -> 30500
A35: 134 | B35: Meena sharma | C35: =PROPER(TRIM(B35)) -> Meena Sharma | D35: IT | E35: =PROPER(TRIM(D35)) -> It | F35: meena@gmail.com | G35: =IF(F35="","Not Available",F35) -> meena@gmail.com | H35: 35000 | I35: =IF(H35="",$H$93,H35) -> 35000 | J35: 45037 | K35: 3000 | L35: =IF(K35="",0,K35) -> 3000 | N35: =IF(M35="","Not Assigned",M35) -> Not Assigned | O35: =IFERROR(I35+L35,0) -> 38000
A36: 135 | B36: John Rao | C36: =PROPER(TRIM(B36)) -> John Rao | D36: Finance | E36: =PROPER(TRIM(D36)) -> Finance | F36: john@gmail.com | G36: =IF(F36="","Not Available",F36) -> john@gmail.com | H36: 40000 | I36: =IF(H36="",$H$93,H36) -> 40000 | J36: 45071 | K36: 4000 | L36: =IF(K36="",0,K36) -> 4000 | M36: Kavitha | N36: =IF(M36="","Not Assigned",M36) -> Kavitha | O36: =IFERROR(I36+L36,0) -> 44000
A37: 136 | B37: Kavya reddy | C37: =PROPER(TRIM(B37)) -> Kavya Reddy | D37: IT | E37: =PROPER(TRIM(D37)) -> It | F37: kavya@gmail.com | G37: =IF(F37="","Not Available",F37) -> kavya@gmail.com | I37: =IF(H37="",$H$93,H37) -> 32091 | J37: 45078 | K37: 1500 | L37: =IF(K37="",0,K37) -> 1500 | M37: Mahesh | N37: =IF(M37="","Not Assigned",M37) -> Mahesh | O37: =IFERROR(I37+L37,0) -> 33591
A38: 137 | B38: Arjun naik | C38: =PROPER(TRIM(B38)) -> Arjun Naik | D38: Sales | E38: =PROPER(TRIM(D38)) -> Sales | F38: arjun@gmail.com | G38: =IF(F38="","Not Available",F38) -> arjun@gmail.com | H38: 27000 | I38: =IF(H38="",$H$93,H38) -> 27000 | J38: 45088 | L38: =IF(K38="",0,K38) -> 0 | M38: Suresh | N38: =IF(M38="","Not Assigned",M38) -> Suresh | O38: =IFERROR(I38+L38,0) -> 27000
A39: 138 | B39: Priya Sharma | C39: =PROPER(TRIM(B39)) -> Priya Sharma | D39: HR | E39: =PROPER(TRIM(D39)) -> Hr | F39: priya@gmail.com | G39: =IF(F39="","Not Available",F39) -> priya@gmail.com | H39: 26000 | I39: =IF(H39="",$H$93,H39) -> 26000 | J39: 45126 | K39: 1800 | L39: =IF(K39="",0,K39) -> 1800 | M39: Kavitha | N39: =IF(M39="","Not Assigned",M39) -> Kavitha | O39: =IFERROR(I39+L39,0) -> 27800
A40: 139 | B40: Rohit verma | C40: =PROPER(TRIM(B40)) -> Rohit Verma | D40: Finance | E40: =PROPER(TRIM(D40)) -> Finance | F40: rohit@gmail.com | G40: =IF(F40="","Not Available",F40) -> rohit@gmail.com | H40: 38000 | I40: =IF(H40="",$H$93,H40) -> 38000 | J40: 45160 | K40: 3500 | L40: =IF(K40="",0,K40) -> 3500 | M40: Kavitha | N40: =IF(M40="","Not Assigned",M40) -> Kavitha | O40: =IFERROR(I40+L40,0) -> 41500
...

Sheet Summary
E2: SUMMARY
E4: Variable | F4: Result
E5: Total Employees | F5: =COUNTA('Cleaned data'!A2:A91) -> 90
E6: Average Salary | F6: =AVERAGE('Cleaned data'!I67:I91) -> 32274.56
E7: Highest Salary | F7: =MAX('Cleaned data'!I2:I91) -> 43000
E8: Lowest Salary | F8: =MIN('Cleaned data'!I2:I91) -> 25000
E9: Total Salary Paid | F9: =SUM('Cleaned data'!I2:I91) -> 2888183
E10: Total Bonus Paid | F10: =SUM('Cleaned data'!L2:L91) -> 134500
